{
	"registryname": "Planetary_mining_machine",
    "localizedname": "行星开采机",
    "color":"3366FF",
    "parts": [
        {
            "x": -1,
            "y": 0,
            "z": 0,
            "elements": [
                "metallurgy:astral_silver_block@0"
            ]
        },
        {
            "x": 0,
            "y": 0,
            "z": 0,
            "elements": [
                "modularmachinery:blockcontroller@2"
            ]
        },
        {
            "x": -2,
            "y": 0,
            "z": 0,
            "elements": [
                "metallurgy:astral_silver_block@0"
            ]
        },
        {
            "x": 1,
            "y": 0,
            "z": 0,
            "elements": [
                "metallurgy:astral_silver_block@0"
            ]
        },
        {
            "x": 2,
            "y": 0,
            "z": 0,
            "elements": [
                "metallurgy:astral_silver_block@0"
            ]
        },
        {
            "x": -3,
            "y": -6,
            "z": 5,
            "elements": [
                "metallurgy:astral_silver_block@0"
            ]
        },
        {
            "x": -2,
            "y": -6,
            "z": 5,
            "elements": [
                "metallurgy:astral_silver_block@0"
            ]
        },
        {
            "x": 2,
            "y": -6,
            "z": 5,
            "elements": [
                "metallurgy:astral_silver_block@0"
            ]
        },
        {
            "x": 3,
            "y": -6,
            "z": 5,
            "elements": [
                "metallurgy:astral_silver_block@0"
            ]
        },
        {
            "x": 1,
            "y": -5,
            "z": -2,
            "elements": [
                "metallurgy:astral_silver_block@0"
            ]
        },
        {
            "x": 0,
            "y": -5,
            "z": -2,
            "elements": [
                "metallurgy:astral_silver_block@0"
            ]
        },
        {
            "x": 1,
            "y": -3,
            "z": -1,
            "elements": [
                "metallurgy:astral_silver_block@0"
            ]
        },
        {
            "x": -1,
            "y": -5,
            "z": -2,
            "elements": [
                "metallurgy:astral_silver_block@0"
            ]
        },
        {
            "x": 0,
            "y": -3,
            "z": -1,
            "elements": [
                "metallurgy:astral_silver_block@0"
            ]
        },
        {
            "x": 1,
            "y": -1,
            "z": 0,
            "elements": [
                "metallurgy:astral_silver_block@0"
            ]
        },
        {
            "x": -2,
            "y": 1,
            "z": 0,
            "elements": [
                "metallurgy:astral_silver_block@0"
            ]
        },
        {
            "x": 0,
            "y": 5,
            "z": 2,
            "elements": [
                "minecraft:beacon@0"
            ]
        },
        {
            "x": -1,
            "y": -3,
            "z": -1,
            "elements": [
                "metallurgy:astral_silver_block@0"
            ]
        },
        {
            "x": 0,
            "y": -1,
            "z": 0,
            "elements": [
                "modularmagic:blockgridproviderinput@0"
            ]
        },
        {
            "x": -1,
            "y": -1,
            "z": 0,
            "elements": [
                "metallurgy:astral_silver_block@0"
            ]
        },
        {
            "x": 2,
            "y": 1,
            "z": 0,
            "elements": [
                "metallurgy:astral_silver_block@0"
            ]
        },
        {
            "x": -3,
            "y": -5,
            "z": 5,
            "elements": [
                "metallurgy:astral_silver_block@0"
            ]
        },
        {
            "x": -3,
            "y": -7,
            "z": 4,
            "elements": [
                "metallurgy:astral_silver_block@0"
            ]
        },
        {
            "x": -2,
            "y": -5,
            "z": 5,
            "elements": [
                "metallurgy:astral_silver_block@0"
            ]
        },
        {
            "x": -2,
            "y": -7,
            "z": 4,
            "elements": [
                "minecraft:lava@0"
            ]
        },
        {
            "x": -1,
            "y": -7,
            "z": 4,
            "elements": [
                "minecraft:lava@0"
            ]
        },
        {
            "x": 0,
            "y": -7,
            "z": 4,
            "elements": [
                "minecraft:lava@0"
            ]
        },
        {
            "x": 1,
            "y": -7,
            "z": 4,
            "elements": [
                "minecraft:lava@0"
            ]
        },
        {
            "x": 2,
            "y": -5,
            "z": 5,
            "elements": [
                "metallurgy:astral_silver_block@0"
            ]
        },
        {
            "x": 2,
            "y": -7,
            "z": 4,
            "elements": [
                "minecraft:lava@0"
            ]
        },
        {
            "x": 3,
            "y": -5,
            "z": 5,
            "elements": [
                "metallurgy:astral_silver_block@0"
            ]
        },
        {
            "x": 3,
            "y": -7,
            "z": 4,
            "elements": [
                "metallurgy:astral_silver_block@0"
            ]
        },
        {
            "x": 1,
            "y": -6,
            "z": -2,
            "elements": [
                "metallurgy:astral_silver_block@0"
            ]
        },
        {
            "x": 0,
            "y": -6,
            "z": -2,
            "elements": [
                "metallurgy:astral_silver_block@0"
            ]
        },
        {
            "x": 1,
            "y": -4,
            "z": -1,
            "elements": [
                "metallurgy:astral_silver_block@0"
            ]
        },
        {
            "x": 2,
            "y": -2,
            "z": 0,
            "elements": [
                "metallurgy:astral_silver_block@0"
            ]
        },
        {
            "x": -1,
            "y": -6,
            "z": -2,
            "elements": [
                "metallurgy:astral_silver_block@0"
            ]
        },
        {
            "x": 0,
            "y": -4,
            "z": -1,
            "elements": [
                "metallurgy:astral_silver_block@0"
            ]
        },
        {
            "x": 1,
            "y": -2,
            "z": 0,
            "elements": [
                "metallurgy:astral_silver_block@0"
            ]
        },
        {
            "x": -2,
            "y": 2,
            "z": 0,
            "elements": [
                "metallurgy:astral_silver_block@0"
            ]
        },
        {
            "x": -1,
            "y": 4,
            "z": 1,
            "elements": [
                "enderio:block_alloy_endergy@3"
            ]
        },
        {
            "x": 0,
            "y": 6,
            "z": 2,
            "elements": [
                "minecraft:stained_glass@1"
            ]
        },
        {
            "x": -1,
            "y": -4,
            "z": -1,
            "elements": [
                "metallurgy:astral_silver_block@0"
            ]
        },
        {
            "x": 0,
            "y": 4,
            "z": 1,
            "elements": [
                "enderio:block_alloy_endergy@3"
            ]
        },
        {
            "x": -1,
            "y": -2,
            "z": 0,
            "elements": [
                "metallurgy:astral_silver_block@0"
            ]
        },
        {
            "x": 1,
            "y": 4,
            "z": 1,
            "elements": [
                "enderio:block_alloy_endergy@3"
            ]
        },
        {
            "x": -2,
            "y": -2,
            "z": 0,
            "elements": [
                "metallurgy:astral_silver_block@0"
            ]
        },
        {
            "x": 2,
            "y": 2,
            "z": 0,
            "elements": [
                "metallurgy:astral_silver_block@0"
            ]
        },
        {
            "x": -3,
            "y": -6,
            "z": 4,
            "elements": [
                "metallurgy:astral_silver_block@0"
            ]
        },
        {
            "x": -1,
            "y": -4,
            "z": 5,
            "elements": [
                "metallurgy:astral_silver_block@0"
            ]
        },
        {
            "x": 0,
            "y": -4,
            "z": 5,
            "elements": [
                "metallurgy:astral_silver_block@0"
            ]
        },
        {
            "x": 1,
            "y": -4,
            "z": 5,
            "elements": [
                "metallurgy:astral_silver_block@0"
            ]
        },
        {
            "x": 3,
            "y": -6,
            "z": 4,
            "elements": [
                "metallurgy:astral_silver_block@0"
            ]
        },
        {
            "x": 3,
            "y": -5,
            "z": -1,
            "elements": [
                "metallurgy:astral_silver_block@0"
            ]
        },
        {
            "x": 1,
            "y": -7,
            "z": -2,
            "elements": [
                "metallurgy:astral_silver_block@0"
            ]
        },
        {
            "x": 2,
            "y": -5,
            "z": -1,
            "elements": [
                "metallurgy:astral_silver_block@0"
            ]
        },
        {
            "x": 0,
            "y": -7,
            "z": -2,
            "elements": [
                "metallurgy:astral_silver_block@0"
            ]
        },
        {
            "x": 2,
            "y": -3,
            "z": 0,
            "elements": [
                "metallurgy:astral_silver_block@0"
            ]
        },
        {
            "x": -3,
            "y": 3,
            "z": 0,
            "elements": [
                "metallurgy:astral_silver_block@0"
            ]
        },
        {
            "x": -1,
            "y": -7,
            "z": -2,
            "elements": [
                "metallurgy:astral_silver_block@0"
            ]
        },
        {
            "x": 1,
            "y": -3,
            "z": 0,
            "elements": [
                "metallurgy:astral_silver_block@0"
            ]
        },
        {
            "x": -1,
            "y": 5,
            "z": 1,
            "elements": [
                "redstonerepository:storage@1"
            ]
        },
        {
            "x": -2,
            "y": -5,
            "z": -1,
            "elements": [
                "metallurgy:astral_silver_block@0"
            ]
        },
        {
            "x": -1,
            "y": -3,
            "z": 0,
            "elements": [
                "metallurgy:astral_silver_block@0"
            ]
        },
        {
            "x": 1,
            "y": 5,
            "z": 1,
            "elements": [
                "redstonerepository:storage@1"
            ]
        },
        {
            "x": -3,
            "y": -5,
            "z": -1,
            "elements": [
                "metallurgy:astral_silver_block@0"
            ]
        },
        {
            "x": -2,
            "y": -3,
            "z": 0,
            "elements": [
                "metallurgy:astral_silver_block@0"
            ]
        },
        {
            "x": 3,
            "y": 3,
            "z": 0,
            "elements": [
                "metallurgy:astral_silver_block@0"
            ]
        },
        {
            "x": -4,
            "y": -7,
            "z": 3,
            "elements": [
                "metallurgy:astral_silver_block@0"
            ]
        },
        {
            "x": -3,
            "y": -5,
            "z": 4,
            "elements": [
                "metallurgy:astral_silver_block@0"
            ]
        },
        {
            "x": -3,
            "y": -7,
            "z": 3,
            "elements": [
                "minecraft:lava@0"
            ]
        },
        {
            "x": -1,
            "y": -3,
            "z": 5,
            "elements": [
                "metallurgy:astral_silver_block@0"
            ]
        },
        {
            "x": -2,
            "y": -7,
            "z": 3,
            "elements": [
                "minecraft:lava@0"
            ]
        },
        {
            "x": 0,
            "y": -3,
            "z": 5,
            "elements": [
                "metallurgy:astral_silver_block@0"
            ]
        },
        {
            "x": -1,
            "y": -7,
            "z": 3,
            "elements": [
                "advancedrocketry:advrocketmotor@0"
            ]
        },
        {
            "x": 1,
            "y": -3,
            "z": 5,
            "elements": [
                "metallurgy:astral_silver_block@0"
            ]
        },
        {
            "x": 0,
            "y": -7,
            "z": 3,
            "elements": [
                "advancedrocketry:advrocketmotor@0"
            ]
        },
        {
            "x": 1,
            "y": -7,
            "z": 3,
            "elements": [
                "advancedrocketry:advrocketmotor@0"
            ]
        },
        {
            "x": 2,
            "y": -7,
            "z": 3,
            "elements": [
                "minecraft:lava@0"
            ]
        },
        {
            "x": 3,
            "y": -5,
            "z": 4,
            "elements": [
                "metallurgy:astral_silver_block@0"
            ]
        },
        {
            "x": 3,
            "y": -7,
            "z": 3,
            "elements": [
                "minecraft:lava@0"
            ]
        },
        {
            "x": 4,
            "y": -7,
            "z": 3,
            "elements": [
                "metallurgy:astral_silver_block@0"
            ]
        },
        {
            "x": 3,
            "y": -6,
            "z": -1,
            "elements": [
                "metallurgy:astral_silver_block@0"
            ]
        },
        {
            "x": 2,
            "y": -6,
            "z": -1,
            "elements": [
                "metallurgy:astral_silver_block@0"
            ]
        },
        {
            "x": 2,
            "y": -4,
            "z": 0,
            "elements": [
                "metallurgy:astral_silver_block@0"
            ]
        },
        {
            "x": -3,
            "y": 4,
            "z": 0,
            "elements": [
                "metallurgy:astral_silver_block@0"
            ]
        },
        {
            "x": 1,
            "y": -4,
            "z": 0,
            "elements": [
                "metallurgy:astral_silver_block@0"
            ]
        },
        {
            "x": -2,
            "y": -6,
            "z": -1,
            "elements": [
                "metallurgy:astral_silver_block@0"
            ]
        },
        {
            "x": -1,
            "y": -4,
            "z": 0,
            "elements": [
                "metallurgy:astral_silver_block@0"
            ]
        },
        {
            "x": -3,
            "y": -6,
            "z": -1,
            "elements": [
                "metallurgy:astral_silver_block@0"
            ]
        },
        {
            "x": -2,
            "y": -4,
            "z": 0,
            "elements": [
                "metallurgy:astral_silver_block@0"
            ]
        },
        {
            "x": 3,
            "y": 4,
            "z": 0,
            "elements": [
                "metallurgy:astral_silver_block@0"
            ]
        },
        {
            "x": -4,
            "y": -6,
            "z": 3,
            "elements": [
                "metallurgy:astral_silver_block@0"
            ]
        },
        {
            "x": -2,
            "y": -4,
            "z": 4,
            "elements": [
                "metallurgy:astral_silver_block@0"
            ]
        },
        {
            "x": -1,
            "y": -2,
            "z": 5,
            "elements": [
                "metallurgy:astral_silver_block@0"
            ]
        },
        {
            "x": -1,
            "y": -4,
            "z": 4,
            "elements": [
                "metallurgy:astral_silver_block@0"
            ]
        },
        {
            "x": 0,
            "y": -2,
            "z": 5,
            "elements": [
                "metallurgy:astral_silver_block@0"
            ]
        },
        {
            "x": 1,
            "y": -2,
            "z": 5,
            "elements": [
                "metallurgy:astral_silver_block@0"
            ]
        },
        {
            "x": 0,
            "y": -6,
            "z": 3,
            "elements": [
                "advancedrocketry:fueltank@0"
            ]
        },
        {
            "x": 1,
            "y": -4,
            "z": 4,
            "elements": [
                "metallurgy:astral_silver_block@0"
            ]
        },
        {
            "x": 2,
            "y": -4,
            "z": 4,
            "elements": [
                "metallurgy:astral_silver_block@0"
            ]
        },
        {
            "x": 4,
            "y": -6,
            "z": 3,
            "elements": [
                "metallurgy:astral_silver_block@0"
            ]
        },
        {
            "x": 3,
            "y": -7,
            "z": -1,
            "elements": [
                "metallurgy:astral_silver_block@0"
            ]
        },
        {
            "x": 2,
            "y": -7,
            "z": -1,
            "elements": [
                "metallurgy:astral_silver_block@0"
            ]
        },
        {
            "x": 3,
            "y": -5,
            "z": 0,
            "elements": [
                "metallurgy:astral_silver_block@0"
            ]
        },
        {
            "x": 1,
            "y": -7,
            "z": -1,
            "elements": [
                "minecraft:lava@0"
            ]
        },
        {
            "x": -3,
            "y": 5,
            "z": 0,
            "elements": [
                "metallurgy:astral_silver_block@0"
            ]
        },
        {
            "x": 0,
            "y": -7,
            "z": -1,
            "elements": [
                "minecraft:lava@0"
            ]
        },
        {
            "x": -2,
            "y": 5,
            "z": 0,
            "elements": [
                "redstonearsenal:storage@1"
            ]
        },
        {
            "x": -1,
            "y": -7,
            "z": -1,
            "elements": [
                "minecraft:lava@0"
            ]
        },
        {
            "x": -2,
            "y": -7,
            "z": -1,
            "elements": [
                "metallurgy:astral_silver_block@0"
            ]
        },
        {
            "x": -3,
            "y": -7,
            "z": -1,
            "elements": [
                "metallurgy:astral_silver_block@0"
            ]
        },
        {
            "x": -3,
            "y": -5,
            "z": 0,
            "elements": [
                "metallurgy:astral_silver_block@0"
            ]
        },
        {
            "x": 2,
            "y": 5,
            "z": 0,
            "elements": [
                "redstonearsenal:storage@1"
            ]
        },
        {
            "x": 3,
            "y": 5,
            "z": 0,
            "elements": [
                "metallurgy:astral_silver_block@0"
            ]
        },
        {
            "x": -4,
            "y": -5,
            "z": 3,
            "elements": [
                "metallurgy:astral_silver_block@0"
            ]
        },
        {
            "x": -4,
            "y": -7,
            "z": 2,
            "elements": [
                "metallurgy:astral_silver_block@0"
            ]
        },
        {
            "x": -2,
            "y": -3,
            "z": 4,
            "elements": [
                "metallurgy:astral_silver_block@0"
            ]
        },
        {
            "x": -3,
            "y": -7,
            "z": 2,
            "elements": [
                "minecraft:lava@0"
            ]
        },
        {
            "x": -1,
            "y": -3,
            "z": 4,
            "elements": [
                "metallurgy:astral_silver_block@0"
            ]
        },
        {
            "x": -2,
            "y": -7,
            "z": 2,
            "elements": [
                "minecraft:lava@0"
            ]
        },
        {
            "x": -1,
            "y": -7,
            "z": 2,
            "elements": [
                "advancedrocketry:advrocketmotor@0"
            ]
        },
        {
            "x": 0,
            "y": -5,
            "z": 3,
            "elements": [
                "advancedrocketry:fueltank@0"
            ]
        },
        {
            "x": 1,
            "y": -3,
            "z": 4,
            "elements": [
                "metallurgy:astral_silver_block@0"
            ]
        },
        {
            "x": 0,
            "y": -7,
            "z": 2,
            "elements": [
                "advancedrocketry:advrocketmotor@0"
            ]
        },
        {
            "x": 2,
            "y": -3,
            "z": 4,
            "elements": [
                "metallurgy:astral_silver_block@0"
            ]
        },
        {
            "x": 1,
            "y": -7,
            "z": 2,
            "elements": [
                "advancedrocketry:advrocketmotor@0"
            ]
        },
        {
            "x": 2,
            "y": -7,
            "z": 2,
            "elements": [
                "minecraft:lava@0"
            ]
        },
        {
            "x": 3,
            "y": -7,
            "z": 2,
            "elements": [
                "minecraft:lava@0"
            ]
        },
        {
            "x": 4,
            "y": -5,
            "z": 3,
            "elements": [
                "metallurgy:astral_silver_block@0"
            ]
        },
        {
            "x": 4,
            "y": -7,
            "z": 2,
            "elements": [
                "metallurgy:astral_silver_block@0"
            ]
        },
        {
            "x": 3,
            "y": -6,
            "z": 0,
            "elements": [
                "metallurgy:astral_silver_block@0"
            ]
        },
        {
            "x": -3,
            "y": -6,
            "z": 0,
            "elements": [
                "metallurgy:astral_silver_block@0"
            ]
        },
        {
            "x": -4,
            "y": -6,
            "z": 2,
            "elements": [
                "metallurgy:astral_silver_block@0"
            ]
        },
        {
            "x": -3,
            "y": -4,
            "z": 3,
            "elements": [
                "metallurgy:astral_silver_block@0"
            ]
        },
        {
            "x": -2,
            "y": -2,
            "z": 4,
            "elements": [
                "metallurgy:astral_silver_block@0"
            ]
        },
        {
            "x": -2,
            "y": -4,
            "z": 3,
            "elements": [
                "metallurgy:astral_silver_block@0"
            ]
        },
        {
            "x": -1,
            "y": -2,
            "z": 4,
            "elements": [
                "metallurgy:astral_silver_block@0"
            ]
        },
        {
            "x": 0,
            "y": -4,
            "z": 3,
            "elements": [
                "advancedrocketry:fueltank@0"
            ]
        },
        {
            "x": 1,
            "y": -2,
            "z": 4,
            "elements": [
                "metallurgy:astral_silver_block@0"
            ]
        },
        {
            "x": 0,
            "y": -6,
            "z": 2,
            "elements": [
                "advancedrocketry:liquidtank@0"
            ]
        },
        {
            "x": 2,
            "y": -2,
            "z": 4,
            "elements": [
                "metallurgy:astral_silver_block@0"
            ]
        },
        {
            "x": 2,
            "y": -4,
            "z": 3,
            "elements": [
                "metallurgy:astral_silver_block@0"
            ]
        },
        {
            "x": 3,
            "y": -4,
            "z": 3,
            "elements": [
                "metallurgy:astral_silver_block@0"
            ]
        },
        {
            "x": 4,
            "y": -6,
            "z": 2,
            "elements": [
                "metallurgy:astral_silver_block@0"
            ]
        },
        {
            "x": 3,
            "y": -7,
            "z": 0,
            "elements": [
                "metallurgy:astral_silver_block@0"
            ]
        },
        {
            "x": 2,
            "y": -7,
            "z": 0,
            "elements": [
                "minecraft:lava@0"
            ]
        },
        {
            "x": 1,
            "y": -7,
            "z": 0,
            "elements": [
                "minecraft:lava@0"
            ]
        },
        {
            "x": 0,
            "y": -7,
            "z": 0,
            "elements": [
                "minecraft:lava@0"
            ]
        },
        {
            "x": -1,
            "y": -7,
            "z": 0,
            "elements": [
                "minecraft:lava@0"
            ]
        },
        {
            "x": -2,
            "y": -7,
            "z": 0,
            "elements": [
                "minecraft:lava@0"
            ]
        },
        {
            "x": -3,
            "y": -7,
            "z": 0,
            "elements": [
                "metallurgy:astral_silver_block@0"
            ]
        },
        {
            "x": -4,
            "y": -5,
            "z": 2,
            "elements": [
                "metallurgy:astral_silver_block@0"
            ]
        },
        {
            "x": -3,
            "y": -3,
            "z": 3,
            "elements": [
                "metallurgy:astral_silver_block@0"
            ]
        },
        {
            "x": -4,
            "y": -7,
            "z": 1,
            "elements": [
                "metallurgy:astral_silver_block@0"
            ]
        },
        {
            "x": -2,
            "y": -3,
            "z": 3,
            "elements": [
                "metallurgy:astral_silver_block@0"
            ]
        },
        {
            "x": -1,
            "y": -1,
            "z": 4,
            "elements": [
                "metallurgy:astral_silver_block@0"
            ]
        },
        {
            "x": -3,
            "y": -7,
            "z": 1,
            "elements": [
                "minecraft:lava@0"
            ]
        },
        {
            "x": -2,
            "y": -7,
            "z": 1,
            "elements": [
                "minecraft:lava@0"
            ]
        },
        {
            "x": 0,
            "y": -3,
            "z": 3,
            "elements": [
                "advancedrocketry:fueltank@0"
            ]
        },
        {
            "x": 1,
            "y": -1,
            "z": 4,
            "elements": [
                "metallurgy:astral_silver_block@0"
            ]
        },
        {
            "x": -1,
            "y": -7,
            "z": 1,
            "elements": [
                "advancedrocketry:advrocketmotor@0"
            ]
        },
        {
            "x": 0,
            "y": -5,
            "z": 2,
            "elements": [
                "advancedrocketry:liquidtank@0"
            ]
        },
        {
            "x": 0,
            "y": -7,
            "z": 1,
            "elements": [
                "advancedrocketry:advrocketmotor@0"
            ]
        },
        {
            "x": 2,
            "y": -3,
            "z": 3,
            "elements": [
                "metallurgy:astral_silver_block@0"
            ]
        },
        {
            "x": 1,
            "y": -7,
            "z": 1,
            "elements": [
                "advancedrocketry:advrocketmotor@0"
            ]
        },
        {
            "x": 3,
            "y": -3,
            "z": 3,
            "elements": [
                "metallurgy:astral_silver_block@0"
            ]
        },
        {
            "x": 2,
            "y": -7,
            "z": 1,
            "elements": [
                "minecraft:lava@0"
            ]
        },
        {
            "x": 3,
            "y": -7,
            "z": 1,
            "elements": [
                "minecraft:lava@0"
            ]
        },
        {
            "x": 4,
            "y": -5,
            "z": 2,
            "elements": [
                "metallurgy:astral_silver_block@0"
            ]
        },
        {
            "x": 4,
            "y": -7,
            "z": 1,
            "elements": [
                "metallurgy:astral_silver_block@0"
            ]
        },
        {
            "x": -3,
            "y": -2,
            "z": 3,
            "elements": [
                "metallurgy:astral_silver_block@0"
            ]
        },
        {
            "x": -2,
            "y": 0,
            "z": 4,
            "elements": [
                "metallurgy:astral_silver_block@0"
            ]
        },
        {
            "x": -4,
            "y": -6,
            "z": 1,
            "elements": [
                "metallurgy:astral_silver_block@0"
            ]
        },
        {
            "x": -3,
            "y": -4,
            "z": 2,
            "elements": [
                "metallurgy:astral_silver_block@0"
            ]
        },
        {
            "x": -2,
            "y": -2,
            "z": 3,
            "elements": [
                "metallurgy:astral_silver_block@0"
            ]
        },
        {
            "x": -1,
            "y": 0,
            "z": 4,
            "elements": [
                "metallurgy:astral_silver_block@0"
            ]
        },
        {
            "x": 0,
            "y": 0,
            "z": 4,
            "elements": [
                "gugu-utils:sparkmanahatch@0"
            ]
        },
        {
            "x": 0,
            "y": -2,
            "z": 3,
            "elements": [
                "advancedrocketry:fueltank@0"
            ]
        },
        {
            "x": 1,
            "y": 0,
            "z": 4,
            "elements": [
                "metallurgy:astral_silver_block@0"
            ]
        },
        {
            "x": 0,
            "y": -4,
            "z": 2,
            "elements": [
                "advancedrocketry:liquidtank@0"
            ]
        },
        {
            "x": 2,
            "y": 0,
            "z": 4,
            "elements": [
                "metallurgy:astral_silver_block@0"
            ]
        },
        {
            "x": 2,
            "y": -2,
            "z": 3,
            "elements": [
                "metallurgy:astral_silver_block@0"
            ]
        },
        {
            "x": 3,
            "y": -2,
            "z": 3,
            "elements": [
                "metallurgy:astral_silver_block@0"
            ]
        },
        {
            "x": 3,
            "y": -4,
            "z": 2,
            "elements": [
                "metallurgy:astral_silver_block@0"
            ]
        },
        {
            "x": 4,
            "y": -6,
            "z": 1,
            "elements": [
                "metallurgy:astral_silver_block@0"
            ]
        },
        {
            "x": -3,
            "y": 3,
            "z": 5,
            "elements": [
                "metallurgy:astral_silver_block@0"
            ]
        },
        {
            "x": -2,
            "y": 3,
            "z": 5,
            "elements": [
                "metallurgy:astral_silver_block@0"
            ]
        },
        {
            "x": -2,
            "y": 1,
            "z": 4,
            "elements": [
                "metallurgy:astral_silver_block@0"
            ]
        },
        {
            "x": 3,
            "y": 5,
            "z": -1,
            "elements": [
                "metallurgy:astral_silver_block@0"
            ]
        },
        {
            "x": -4,
            "y": -5,
            "z": 1,
            "elements": [
                "metallurgy:astral_silver_block@0"
            ]
        },
        {
            "x": -3,
            "y": -3,
            "z": 2,
            "elements": [
                "metallurgy:astral_silver_block@0"
            ]
        },
        {
            "x": -2,
            "y": -1,
            "z": 3,
            "elements": [
                "metallurgy:astral_silver_block@0"
            ]
        },
        {
            "x": 2,
            "y": 5,
            "z": -1,
            "elements": [
                "metallurgy:astral_silver_block@0"
            ]
        },
        {
            "x": 0,
            "y": -1,
            "z": 3,
            "elements": [
                "advancedrocketry:fueltank@0"
            ]
        },
        {
            "x": 2,
            "y": 3,
            "z": 5,
            "elements": [
                "metallurgy:astral_silver_block@0"
            ]
        },
        {
            "x": 0,
            "y": -3,
            "z": 2,
            "elements": [
                "advancedrocketry:liquidtank@0"
            ]
        },
        {
            "x": 2,
            "y": 1,
            "z": 4,
            "elements": [
                "metallurgy:astral_silver_block@0"
            ]
        },
        {
            "x": 3,
            "y": 3,
            "z": 5,
            "elements": [
                "metallurgy:astral_silver_block@0"
            ]
        },
        {
            "x": 2,
            "y": -1,
            "z": 3,
            "elements": [
                "metallurgy:astral_silver_block@0"
            ]
        },
        {
            "x": -2,
            "y": 5,
            "z": -1,
            "elements": [
                "metallurgy:astral_silver_block@0"
            ]
        },
        {
            "x": -3,
            "y": 5,
            "z": -1,
            "elements": [
                "metallurgy:astral_silver_block@0"
            ]
        },
        {
            "x": 3,
            "y": -3,
            "z": 2,
            "elements": [
                "metallurgy:astral_silver_block@0"
            ]
        },
        {
            "x": 4,
            "y": -5,
            "z": 1,
            "elements": [
                "metallurgy:astral_silver_block@0"
            ]
        },
        {
            "x": -3,
            "y": 4,
            "z": 5,
            "elements": [
                "metallurgy:astral_silver_block@0"
            ]
        },
        {
            "x": -2,
            "y": 4,
            "z": 5,
            "elements": [
                "metallurgy:astral_silver_block@0"
            ]
        },
        {
            "x": -2,
            "y": 2,
            "z": 4,
            "elements": [
                "metallurgy:astral_silver_block@0"
            ]
        },
        {
            "x": 3,
            "y": 4,
            "z": -1,
            "elements": [
                "metallurgy:astral_silver_block@0"
            ]
        },
        {
            "x": -3,
            "y": -2,
            "z": 2,
            "elements": [
                "metallurgy:astral_silver_block@0"
            ]
        },
        {
            "x": -2,
            "y": 0,
            "z": 3,
            "elements": [
                "metallurgy:astral_silver_block@0"
            ]
        },
        {
            "x": 2,
            "y": 4,
            "z": -1,
            "elements": [
                "metallurgy:astral_silver_block@0"
            ]
        },
        {
            "x": -3,
            "y": -4,
            "z": 1,
            "elements": [
                "metallurgy:astral_silver_block@0"
            ]
        },
        {
            "x": -1,
            "y": 0,
            "z": 3,
            "elements": [
                "metallurgy:astral_silver_reinforced_glass@0"
            ]
        },
        {
            "x": -2,
            "y": -4,
            "z": 1,
            "elements": [
                "metallurgy:astral_silver_block@0"
            ]
        },
        {
            "x": 0,
            "y": 0,
            "z": 3,
            "elements": [
                "modularmachinery:blockfluidinputhatch"
            ]
        },
        {
            "x": 2,
            "y": 4,
            "z": 5,
            "elements": [
                "metallurgy:astral_silver_block@0"
            ]
        },
        {
            "x": 0,
            "y": -2,
            "z": 2,
            "elements": [
                "advancedrocketry:liquidtank@0"
            ]
        },
        {
            "x": 1,
            "y": 0,
            "z": 3,
            "elements": [
                "metallurgy:astral_silver_reinforced_glass@0"
            ]
        },
        {
            "x": 2,
            "y": 2,
            "z": 4,
            "elements": [
                "metallurgy:astral_silver_block@0"
            ]
        },
        {
            "x": 3,
            "y": 4,
            "z": 5,
            "elements": [
                "metallurgy:astral_silver_block@0"
            ]
        },
        {
            "x": 2,
            "y": 0,
            "z": 3,
            "elements": [
                "metallurgy:astral_silver_block@0"
            ]
        },
        {
            "x": -2,
            "y": 4,
            "z": -1,
            "elements": [
                "metallurgy:astral_silver_block@0"
            ]
        },
        {
            "x": -3,
            "y": 4,
            "z": -1,
            "elements": [
                "metallurgy:astral_silver_block@0"
            ]
        },
        {
            "x": 2,
            "y": -4,
            "z": 1,
            "elements": [
                "metallurgy:astral_silver_block@0"
            ]
        },
        {
            "x": 3,
            "y": -2,
            "z": 2,
            "elements": [
                "metallurgy:astral_silver_block@0"
            ]
        },
        {
            "x": 3,
            "y": -4,
            "z": 1,
            "elements": [
                "metallurgy:astral_silver_block@0"
            ]
        },
        {
            "x": -3,
            "y": 5,
            "z": 5,
            "elements": [
                "metallurgy:astral_silver_block@0"
            ]
        },
        {
            "x": -3,
            "y": 3,
            "z": 4,
            "elements": [
                "metallurgy:astral_silver_block@0"
            ]
        },
        {
            "x": -2,
            "y": 5,
            "z": 5,
            "elements": [
                "metallurgy:astral_silver_block@0"
            ]
        },
        {
            "x": 3,
            "y": 3,
            "z": -1,
            "elements": [
                "metallurgy:astral_silver_block@0"
            ]
        },
        {
            "x": 2,
            "y": 3,
            "z": -1,
            "elements": [
                "metallurgy:astral_silver_block@0"
            ]
        },
        {
            "x": -3,
            "y": -3,
            "z": 1,
            "elements": [
                "metallurgy:astral_silver_block@0"
            ]
        },
        {
            "x": -2,
            "y": -3,
            "z": 1,
            "elements": [
                "metallurgy:astral_silver_block@0"
            ]
        },
        {
            "x": 2,
            "y": 5,
            "z": 5,
            "elements": [
                "metallurgy:astral_silver_block@0"
            ]
        },
        {
            "x": 0,
            "y": -1,
            "z": 2,
            "elements": [
                "advancedrocketry:liquidtank@0"
            ]
        },
        {
            "x": 3,
            "y": 5,
            "z": 5,
            "elements": [
                "metallurgy:astral_silver_block@0"
            ]
        },
        {
            "x": 3,
            "y": 3,
            "z": 4,
            "elements": [
                "metallurgy:astral_silver_block@0"
            ]
        },
        {
            "x": -2,
            "y": 3,
            "z": -1,
            "elements": [
                "metallurgy:astral_silver_block@0"
            ]
        },
        {
            "x": -3,
            "y": 3,
            "z": -1,
            "elements": [
                "metallurgy:astral_silver_block@0"
            ]
        },
        {
            "x": 2,
            "y": -3,
            "z": 1,
            "elements": [
                "metallurgy:astral_silver_block@0"
            ]
        },
        {
            "x": 3,
            "y": -3,
            "z": 1,
            "elements": [
                "metallurgy:astral_silver_block@0"
            ]
        },
        {
            "x": -3,
            "y": 4,
            "z": 4,
            "elements": [
                "metallurgy:astral_silver_block@0"
            ]
        },
        {
            "x": -3,
            "y": -2,
            "z": 1,
            "elements": [
                "metallurgy:astral_silver_block@0"
            ]
        },
        {
            "x": -2,
            "y": 0,
            "z": 2,
            "elements": [
                "modularmachinery:blockenergyinputhatch"
            ]
        },
        {
            "x": -2,
            "y": -2,
            "z": 1,
            "elements": [
                "metallurgy:astral_silver_block@0"
            ]
        },
        {
            "x": -1,
            "y": 0,
            "z": 2,
            "elements": [
                "metallurgy:astral_silver_reinforced_glass@0"
            ]
        },
        {
            "x": 0,
            "y": 0,
            "z": 2,
            "elements": [
                "modularmachinery:blockoutputbus"
            ]
        },
        {
            "x": 1,
            "y": 0,
            "z": 2,
            "elements": [
                "metallurgy:astral_silver_reinforced_glass@0"
            ]
        },
        {
            "x": 3,
            "y": 4,
            "z": 4,
            "elements": [
                "metallurgy:astral_silver_block@0"
            ]
        },
        {
            "x": 2,
            "y": 0,
            "z": 2,
            "elements": [
                "gugu-utils:environmenthatch@0"
            ]
        },
        {
            "x": 2,
            "y": -2,
            "z": 1,
            "elements": [
                "metallurgy:astral_silver_block@0"
            ]
        },
        {
            "x": 3,
            "y": -2,
            "z": 1,
            "elements": [
                "metallurgy:astral_silver_block@0"
            ]
        },
        {
            "x": -3,
            "y": 5,
            "z": 4,
            "elements": [
                "metallurgy:astral_silver_block@0"
            ]
        },
        {
            "x": -2,
            "y": 5,
            "z": 4,
            "elements": [
                "redstonearsenal:storage@1"
            ]
        },
        {
            "x": -2,
            "y": -1,
            "z": 1,
            "elements": [
                "metallurgy:astral_silver_block@0"
            ]
        },
        {
            "x": 2,
            "y": 5,
            "z": 4,
            "elements": [
                "redstonearsenal:storage@1"
            ]
        },
        {
            "x": 3,
            "y": 5,
            "z": 4,
            "elements": [
                "metallurgy:astral_silver_block@0"
            ]
        },
        {
            "x": 2,
            "y": -1,
            "z": 1,
            "elements": [
                "metallurgy:astral_silver_block@0"
            ]
        },
        {
            "x": -1,
            "y": -7,
            "z": 6,
            "elements": [
                "metallurgy:astral_silver_block@0"
            ]
        },
        {
            "x": 0,
            "y": -7,
            "z": 6,
            "elements": [
                "metallurgy:astral_silver_block@0"
            ]
        },
        {
            "x": 1,
            "y": -7,
            "z": 6,
            "elements": [
                "metallurgy:astral_silver_block@0"
            ]
        },
        {
            "x": -1,
            "y": 4,
            "z": 3,
            "elements": [
                "enderio:block_alloy_endergy@3"
            ]
        },
        {
            "x": -2,
            "y": 0,
            "z": 1,
            "elements": [
                "metallurgy:astral_silver_block@0"
            ]
        },
        {
            "x": 0,
            "y": 4,
            "z": 3,
            "elements": [
                "enderio:block_alloy_endergy@3"
            ]
        },
        {
            "x": -1,
            "y": 0,
            "z": 1,
            "elements": [
                "metallurgy:astral_silver_reinforced_glass@0"
            ]
        },
        {
            "x": 1,
            "y": 4,
            "z": 3,
            "elements": [
                "enderio:block_alloy_endergy@3"
            ]
        },
        {
            "x": 0,
            "y": 0,
            "z": 1,
            "elements": [
                "metallurgy:astral_silver_reinforced_glass@0"
            ]
        },
        {
            "x": 1,
            "y": 0,
            "z": 1,
            "elements": [
                "metallurgy:astral_silver_reinforced_glass@0"
            ]
        },
        {
            "x": 2,
            "y": 0,
            "z": 1,
            "elements": [
                "metallurgy:astral_silver_block@0"
            ]
        },
        {
            "x": -1,
            "y": -6,
            "z": 6,
            "elements": [
                "metallurgy:astral_silver_block@0"
            ]
        },
        {
            "x": 0,
            "y": -6,
            "z": 6,
            "elements": [
                "metallurgy:astral_silver_block@0"
            ]
        },
        {
            "x": 1,
            "y": -6,
            "z": 6,
            "elements": [
                "metallurgy:astral_silver_block@0"
            ]
        },
        {
            "x": -1,
            "y": 5,
            "z": 3,
            "elements": [
                "redstonerepository:storage@1"
            ]
        },
        {
            "x": 1,
            "y": 5,
            "z": 3,
            "elements": [
                "redstonerepository:storage@1"
            ]
        },
        {
            "x": -3,
            "y": -7,
            "z": 5,
            "elements": [
                "metallurgy:astral_silver_block@0"
            ]
        },
        {
            "x": -2,
            "y": -7,
            "z": 5,
            "elements": [
                "metallurgy:astral_silver_block@0"
            ]
        },
        {
            "x": -1,
            "y": -5,
            "z": 6,
            "elements": [
                "metallurgy:astral_silver_block@0"
            ]
        },
        {
            "x": -1,
            "y": -7,
            "z": 5,
            "elements": [
                "minecraft:lava@0"
            ]
        },
        {
            "x": 0,
            "y": -5,
            "z": 6,
            "elements": [
                "metallurgy:astral_silver_block@0"
            ]
        },
        {
            "x": 0,
            "y": -7,
            "z": 5,
            "elements": [
                "minecraft:lava@0"
            ]
        },
        {
            "x": 1,
            "y": -5,
            "z": 6,
            "elements": [
                "metallurgy:astral_silver_block@0"
            ]
        },
        {
            "x": 1,
            "y": -7,
            "z": 5,
            "elements": [
                "minecraft:lava@0"
            ]
        },
        {
            "x": 2,
            "y": -7,
            "z": 5,
            "elements": [
                "metallurgy:astral_silver_block@0"
            ]
        },
        {
            "x": 3,
            "y": -7,
            "z": 5,
            "elements": [
                "metallurgy:astral_silver_block@0"
            ]
        },
        {
            "x": 1,
            "y": -2,
            "z": -1,
            "elements": [
                "metallurgy:astral_silver_block@0"
            ]
        },
        {
            "x": -1,
            "y": 4,
            "z": 2,
            "elements": [
                "enderio:block_alloy_endergy@3"
            ]
        },
        {
            "x": 0,
            "y": -2,
            "z": -1,
            "elements": [
                "metallurgy:astral_silver_block@0"
            ]
        },
        {
            "x": 0,
            "y": 4,
            "z": 2,
            "elements": [
                "enderio:block_alloy_endergy@3"
            ]
        },
        {
            "x": -1,
            "y": -2,
            "z": -1,
            "elements": [
                "metallurgy:astral_silver_block@0"
            ]
        },
        {
            "x": 1,
            "y": 4,
            "z": 2,
            "elements": [
                "enderio:block_alloy_endergy@3"
            ]
        }
    ]}